Workbook

Sheet Dashboard
B2: 📊 DASHBOARD DE GESTÃO DE PROJETOS DE TI
B3: ="Projeto: "&'Parâmetros'!B3&" | Gerente: "&'Parâmetros'!B4&" | Data do Status: "&'Parâmetros'!B8 -> Projeto: Kybernus CLI | Gerente: Guilherme Marafon | Data do Status: 20/05/2026
B5: STATUS GERAL | D5: % DE CONCLUSÃO | F5: ADERÊNCIA DE ENTREGAS | H5: ATIVIDADES ATRASADAS | J5: ORÇAMENTO CONSUMIDO
B6: =IF(AND(E11>=0.95,E12>=0.95),"🟢 NO PRAZO",IF(OR(E11<0.85,E12<0.85),"🔴 CRÍTICO","🟡 ATENÇÃO")) -> 🔴 CRÍTICO | D6: ='Parâmetros'!B16/'Parâmetros'!B15 -> 0.375 | F6: ='Parâmetros'!B14/'Parâmetros'!B13 -> 5.3333333 | H6: ='Parâmetros'!B17 -> 9 | J6: ='Parâmetros'!B10/'Parâmetros'!B9 -> 0.61333333
B9: ⏱ INDICADORES DE PRAZO E CUSTO (EVM)
B10: Indicador | E10: Valor | F10: Faixa | G10: Semáforo | H10: Interpretação
B11: CPI - Índice de Desempenho de Custo | E11: ='Parâmetros'!B11/'Parâmetros'!B10 -> 1.0597826 | F11: ≥ 0,95 | G11: ● | H11: =IF(E11>=1,"Eficiência de custo OK",IF(E11>=0.95,"Custo levemente acima","Estouro de custo")) -> Eficiência de custo OK
B12: SPI - Índice de Desempenho de Prazo | E12: ='Parâmetros'!B16/'Parâmetros'!B15 -> 0.375 | F12: ≥ 0,95 | G12: ● | H12: =IF(E12>=1,"Cronograma no ritmo",IF(E12>=0.95,"Leve atraso","Atraso significativo")) -> Atraso significativo
B13: CV - Variação de Custo (R$) | E13: ='Parâmetros'!B11-'Parâmetros'!B10 -> 55000 | F13: ≥ 0 | G13: ● | H13: =IF(E13>=0,"EV maior que AC - custo OK","Gastando mais que o entregue") -> EV maior que AC - custo OK
B14: Aderência de Entregas (%) | E14: ='Parâmetros'!B14/'Parâmetros'!B13 -> 5.3333333 | F14: ≥ 90% | G14: ● | H14: =IF(E14>=0.9,"Entregas no ritmo",IF(E14>=0.7,"Entregas com atraso leve","Aderência baixa")) -> Entregas no ritmo
B16: 📈 INDICADORES VISUAIS - VISÃO GRÁFICA
B17: 💰 EVOLUÇÃO DE CUSTOS E ENTREGAS
B36: 🎯 ANÁLISE DE RISCOS E TENDÊNCIA DE ENTREGAS
B56: 🎯 PRÓXIMOS MARCOS E TOP RISCOS
B57: 🎯 PRÓXIMOS MARCOS | G57: ⚠ TOP RISCOS CRÍTICOS
B58: ID | C58: Marco | E58: Data Prevista | F58: Data Realizada | G58: ID | H58: Descrição | J58: Severidade | K58: Categoria
B59: =Marcos!A7 -> M04 | C59: =Marcos!B7 -> Encerramento da fase de desenvolvimento | E59: =Marcos!C7 -> 20/06/2026 | F59: 46198 | G59: =Riscos!A4 -> R01 | H59: =Riscos!B4 -> Atraso na integração com SAP por dependência de fornecedor externo | J59: =Riscos!F4 -> 25 | K59: =Riscos!C4 -> Técnico
B60: =Marcos!A8 -> M05 | C60: =Marcos!B8 -> Início dos testes integrados | E60: =Marcos!C8 -> 21/06/2026 | F60: 46194 | G60: =Riscos!A5 -> R02 | H60: =Riscos!B5 -> Mudança de escopo solicitada pela área financeira | J60: =Riscos!F5 -> 16 | K60: =Riscos!C5 -> Escopo
B61: =Marcos!A9 -> M06 | C61: =Marcos!B9 -> Conclusão do UAT | E61: =Marcos!C9 -> 10/07/2026 | F61: 46213 | G61: =Riscos!A6 -> R03 | H61: =Riscos!B6 -> Indisponibilidade de usuários-chave para UAT | J61: =Riscos!F6 -> 12 | K61: =Riscos!C6 -> Recursos
B62: =Marcos!A10 -> M07 | C62: =Marcos!B10 -> Treinamento concluído | E62: =Marcos!C10 -> 30/07/2026 | F62: 46233 | G62: =Riscos!A7 -> R04 | H62: =Riscos!B7 -> Falhas de segurança detectadas em pentest | J62: =Riscos!F7 -> 15 | K62: =Riscos!C7 -> Segurança
B63: =Marcos!A11 -> M08 | C63: =Marcos!B11 -> Go-Live em produção | E63: =Marcos!C11 -> 20/08/2026 | F63: 46262 | G63: =Riscos!A8 -> R05 | H63: =Riscos!B8 -> Estouro de orçamento por horas extras de desenvolvimento | J63: =Riscos!F8 -> 9 | K63: =Riscos!C8 -> Custo
B64: =Marcos!A12 -> M09 | C64: =Marcos!B12 -> Encerramento do projeto | E64: =Marcos!C12 -> 30/11/2026 | F64: 46356 | G64: =Riscos!A9 -> R06 | H64: =Riscos!B9 -> Resistência de usuários à nova interface | J64: =Riscos!F9 -> 9 | K64: =Riscos!C9 -> Pessoas
B67: 🚨 ATIVIDADES ATRASADAS | G67: 🛑 PROBLEMAS / IMPEDIMENTOS
B68: ID | C68: Atividade | E68: Atraso (dias) | F68: % Concl. | G68: ID | H68: Descrição | J68: Prioridade | K68: Status
B69: =Atividades!A12 -> A09 | C69: =Atividades!B12 -> Integração com Banco - API | E69: =Atividades!H12 -> 5 | F69: =Atividades!F12 -> 0.7 | G69: =Problemas!A4 -> P01 | H69: =Problemas!B4 -> API do banco parceiro retornando erro 500 intermitente | J69: =Problemas!E4 -> Alta | K69: =Problemas!F4 -> Em Tratamento
B70: =Atividades!A13 -> A10 | C70: =Atividades!B13 -> Integração com SAP | E70: =Atividades!H13 -> 2 | F70: =Atividades!F13 -> 0.5 | G70: =Problemas!A5 -> P02 | H70: =Problemas!B5 -> Ambiente de homologação indisponível por 2 dias | J70: =Problemas!E5 -> Alta | K70: =Problemas!F5 -> Em Tratamento
B71: =Atividades!A14 -> A11 | C71: =Atividades!B14 -> Interface Web - Painéis | E71: =Atividades!H14 -> 10 | F71: =Atividades!F14 -> 0.4 | G71: =Problemas!A6 -> P03 | H71: =Problemas!B6 -> Falta de definição de regra de cálculo de juros | J71: =Problemas!E6 -> Média | K71: =Problemas!F6 -> Aberto
B72: =Atividades!A16 -> A13 | C72: =Atividades!B16 -> Migração de dados legados | E72: =Atividades!H16 -> 8 | F72: =Atividades!F16 -> 0.2 | G72: =Problemas!A7 -> P04 | H72: =Problemas!B7 -> Recurso de QA em férias sem cobertura prevista | J72: =Problemas!E7 -> Média | K72: =Problemas!F7 -> Em Tratamento
B73: =Atividades!A24 -> A21 | C73: =Atividades!B24 -> Documentação técnica módulos | E73: =Atividades!H24 -> 5 | F73: =Atividades!F24 -> 0.3 | G73: =Problemas!A8 -> P05 | H73: =Problemas!B8 -> Pentest apontou 3 vulnerabilidades médias | J73: =Problemas!E8 -> Alta | K73: =Problemas!F8 -> Aberto
B74: =Atividades!A25 -> A22 | C74: =Atividades!B25 -> Revisão de segurança | E74: =Atividades!H25 -> 4 | F74: =Atividades!F25 -> 0.45 | G74: =Problemas!A9 -> P06 | H74: =Problemas!B9 -> Documentação técnica desatualizada para 2 módulos | J74: =Problemas!E9 -> Baixa | K74: =Problemas!F9 -> Aberto
B83: AUX_Status | C83: AUX_Qtd | E83: AUX_Categoria | F83: AUX_Valor | H83: Faixa | I83: Qtd | K83: Prioridade | L83: Qtd
B84: Concluídas | C84: ='Parâmetros'!B14 -> 80 | E84: Consumido | F84: ='Parâmetros'!B10 -> 920000 | H84: Crítico (≥15) | I84: =COUNTIF(Riscos!F4:F13,">=15") -> 3 | K84: Alta | L84: =COUNTIF(Problemas!E4:E10,"Alta") -> 4
B85: Em Andamento | C85: ='Parâmetros'!B15 -> 48 | E85: Disponível | F85: ='Parâmetros'!B9-'Parâmetros'!B10 -> 580000 | H85: Médio (8-14) | I85: =COUNTIFS(Riscos!F4:F13,">=8",Riscos!F4:F13,"<=14") -> 6 | K85: Média | L85: =COUNTIF(Problemas!E4:E10,"Média") -> 2
B86: Atrasadas | C86: ='Parâmetros'!B17 -> 9 | H86: Baixo (≤7) | I86: =COUNTIF(Riscos!F4:F13,"<=7") -> 1 | K86: Baixa | L86: =COUNTIF(Problemas!E4:E10,"Baixa") -> 1
B87: Não Iniciadas | C87: ='Parâmetros'!B18 -> 5
B93: Categoria | C93: Severidade Total
B94: Técnico | C94: =SUMIF(Riscos!C4:C13,B94,Riscos!F4:F13) -> 33
B95: Escopo | C95: =SUMIF(Riscos!C4:C13,B95,Riscos!F4:F13) -> 16
B96: Recursos | C96: =SUMIF(Riscos!C4:C13,B96,Riscos!F4:F13) -> 12
B97: Segurança | C97: =SUMIF(Riscos!C4:C13,B97,Riscos!F4:F13) -> 15
...

Sheet Parâmetros
A1: PARÂMETROS DO PROJETO
A3: Nome do Projeto | B3: Kybernus CLI | D3: 💡 Esta aba centraliza todas as variáveis do projeto.
A4: Gerente do Projeto | B4: Guilherme Marafon | D4: Alterando os valores aqui, o Dashboard se atualiza automaticamente.
A5: Sponsor | B5: Diretor de TI - Roberto Lima | D5: Células azul-claras = rótulos | Células brancas = valores editáveis.
A6: Data de Início | B6: 01/02/2026
A7: Data de Término Planejada | B7: 30/11/2026
A8: Data de Status (Reporte) | B8: 20/05/2026
A9: Orçamento Planejado (R$) | B9: 1500000
A10: Custo Real Acumulado (R$) | B10: 920000
A11: Valor Agregado - EV (R$) | B11: 975000
A12: Total de Entregas Planejadas | B12: 24
A13: Total de Entregas Realizadas | B13: 15
A14: Total de Atividades | B14: 80
A15: Atividades Concluídas | B15: 48
A16: Atividades Em Andamento | B16: 18
A17: Atividades Atrasadas | B17: 9
A18: Atividades Não Iniciadas | B18: 5

Sheet Atividades
A1: LISTA DE ATIVIDADES DO PROJETO
A3: ID | B3: Atividade | C3: Responsável | D3: Início Planejado | E3: Fim Planejado | F3: % Concluído | G3: Status | H3: Dias de Atraso
A4: A01 | B4: Levantamento de requisitos | C4: Equipe Análise | D4: 01/02/2026 | E4: 28/02/2026 | F4: 1 | G4: Concluído | H4: 0
A5: A02 | B5: Modelagem de processos AS-IS | C5: Equipe Análise | D5: 10/02/2026 | E5: 10/03/2026 | F5: 1 | G5: Concluído | H5: 0
A6: A03 | B6: Modelagem de processos TO-BE | C6: Equipe Análise | D6: 01/03/2026 | E6: 31/03/2026 | F6: 1 | G6: Concluído | H6: 0
A7: A04 | B7: Arquitetura de solução | C7: Arquiteto TI | D7: 15/03/2026 | E7: 15/04/2026 | F7: 1 | G7: Concluído | H7: 0
A8: A05 | B8: Setup de ambiente DEV | C8: Infraestrutura | D8: 01/04/2026 | E8: 20/04/2026 | F8: 1 | G8: Concluído | H8: 0
A9: A06 | B9: Desenvolvimento - Contas a Pagar | C9: Dev Backend | D9: 20/04/2026 | E9: 20/05/2026 | F9: 0.85 | G9: Em Andamento | H9: 0
A10: A07 | B10: Desenvolvimento - Contas a Receber | C10: Dev Backend | D10: 01/05/2026 | E10: 30/05/2026 | F10: 0.6 | G10: Em Andamento | H10: 0
A11: A08 | B11: Desenvolvimento - Fluxo de Caixa | C11: Dev Backend | D11: 10/05/2026 | E11: 10/06/2026 | F11: 0.3 | G11: Em Andamento | H11: 0
A12: A09 | B12: Integração com Banco - API | C12: Dev Integração | D12: 01/05/2026 | E12: 15/05/2026 | F12: 0.7 | G12: Atrasado | H12: 5
A13: A10 | B13: Integração com SAP | C13: Dev Integração | D13: 05/05/2026 | E13: 18/05/2026 | F13: 0.5 | G13: Atrasado | H13: 2
A14: A11 | B14: Interface Web - Painéis | C14: Dev Frontend | D14: 01/05/2026 | E14: 10/05/2026 | F14: 0.4 | G14: Atrasado | H14: 10
A15: A12 | B15: Interface Web - Relatórios | C15: Dev Frontend | D15: 10/05/2026 | E15: 20/05/2026 | F15: 0.3 | G15: Atrasado | H15: 0
... A27: A24 | B27: Aprovação compliance | C27: Jurídico | D27: 10/05/2026 | E27: 17/05/2026 | F27: 0.1 | G27: Atrasado | H27: 3

Sheet Riscos
A1: MATRIZ DE RISCOS
A3: ID | B3: Descrição do Risco | C3: Categoria | D3: Probabilidade (1-5) | E3: Impacto (1-5) | F3: Severidade | G3: Resposta | I3: Categoria | J3: Qtd Riscos | K3: Severidade Total
A4: R01 | B4: Atraso na integração com SAP por dependência de fornecedor externo | C4: Técnico | D4: 5 | E4: 5 | F4: =D4*E4 -> 25 | G4: Mitigar - reuniões semanais c/ fornecedor e plano B | I4: Técnico | J4: =COUNTIF(C4:C13,I4) -> 2 | K4: =SUMIF(C4:C13,I4,F4:F13) -> 33
A5: R02 | B5: Mudança de escopo solicitada pela área financeira | C5: Escopo | D5: 4 | E5: 4 | F5: =D5*E5 -> 16 | G5: Aceitar com controle de mudança formal | I5: Escopo | J5: =COUNTIF(C4:C13,I5) -> 1 | K5: =SUMIF(C4:C13,I5,F4:F13) -> 16
A6: R03 | B6: Indisponibilidade de usuários-chave para UAT | C6: Recursos | D6: 3 | E6: 4 | F6: =D6*E6 -> 12 | G6: Mitigar - alocar suplentes treinados | I6: Recursos | J6: =COUNTIF(C4:C13,I6) -> 1 | K6: =SUMIF(C4:C13,I6,F4:F13) -> 12
A7: R04 | B7: Falhas de segurança detectadas em pentest | C7: Segurança | D7: 3 | E7: 5 | F7: =D7*E7 -> 15 | G7: Mitigar - revisão antecipada e patches | I7: Segurança | J7: =COUNTIF(C4:C13,I7) -> 1 | K7: =SUMIF(C4:C13,I7,F4:F13) -> 15
A8: R05 | B8: Estouro de orçamento por horas extras de desenvolvimento | C8: Custo | D8: 3 | E8: 3 | F8: =D8*E8 -> 9 | G8: Monitorar e reaprovar contingência | I8: Custo | J8: =COUNTIF(C4:C13,I8) -> 1 | K8: =SUMIF(C4:C13,I8,F4:F13) -> 9
A9: R06 | B9: Resistência de usuários à nova interface | C9: Pessoas | D9: 3 | E9: 3 | F9: =D9*E9 -> 9 | G9: Mitigar - plano de change management | I9: Pessoas | J9: =COUNTIF(C4:C13,I9) -> 2 | K9: =SUMIF(C4:C13,I9,F4:F13) -> 15
A10: R07 | B10: Performance abaixo do esperado em volumes reais | C10: Técnico | D10: 2 | E10: 4 | F10: =D10*E10 -> 8 | G10: Mitigar - testes de carga em ambiente espelho | I10: Infra | J10: =COUNTIF(C4:C13,I10) -> 1 | K10: =SUMIF(C4:C13,I10,F4:F13) -> 8
A11: R08 | B11: Indisponibilidade do ambiente em cloud | C11: Infra | D11: 2 | E11: 4 | F11: =D11*E11 -> 8 | G11: Transferir - SLA reforçado com provedor | I11: Externo | J11: =COUNTIF(C4:C13,I11) -> 1 | K11: =SUMIF(C4:C13,I11,F4:F13) -> 10
A12: R09 | B12: Saída de membro-chave da equipe técnica | C12: Pessoas | D12: 2 | E12: 3 | F12: =D12*E12 -> 6 | G12: Mitigar - pareamento e documentação
A13: R10 | B13: Mudança regulatória em compliance financeiro | C13: Externo | D13: 2 | E13: 5 | F13: =D13*E13 -> 10 | G13: Monitorar - acompanhar publicações regulatórias

Sheet Marcos
A1: MARCOS DO PROJETO
A3: ID | B3: Marco | C3: Data Planejada | D3: Status | E3: Observação
A4: M01 | B4: Kick-off do projeto | C4: 01/02/2026 | D4: Concluído | E4: Realizado conforme planejado
A5: M02 | B5: Aprovação de requisitos | C5: 28/02/2026 | D5: Concluído | E5: Aprovado pelo sponsor
A6: M03 | B6: Aprovação da arquitetura | C6: 15/04/2026 | D6: Concluído | E6: Comitê técnico aprovou
A7: M04 | B7: Encerramento da fase de desenvolvimento | C7: 20/06/2026 | D7: Em Andamento | E7: Risco de atraso de 1 semana
A8: M05 | B8: Início dos testes integrados | C8: 21/06/2026 | D8: Próximo | E8: Depende de fechamento do DEV
A9: M06 | B9: Conclusão do UAT | C9: 10/07/2026 | D9: Próximo | E9: Usuários-chave já notificados
A10: M07 | B10: Treinamento concluído | C10: 30/07/2026 | D10: Próximo | E10: Material em produção
A11: M08 | B11: Go-Live em produção | C11: 20/08/2026 | D11: Próximo | E11: Janela de corte planejada
A12: M09 | B12: Encerramento do projeto | C12: 30/11/2026 | D12: Próximo | E12: Depende de estabilização

Sheet Entregas
A1: ENTREGAS PREVISTAS x REALIZADAS
A3: Mês | B3: Previstas | C3: Realizadas | D3: Aderência (%) | E3: Acumulado Realizado
A4: Fev/26 | B4: 3 | C4: 3 | D4: =IFERROR(C4/B4,0) -> 1 | E4: =C4 -> 3
A5: Mar/26 | B5: 3 | C5: 3 | D5: =IFERROR(C5/B5,0) -> 1 | E5: =E4+C5 -> 6
A6: Abr/26 | B6: 4 | C6: 4 | D6: =IFERROR(C6/B6,0) -> 1 | E6: =E5+C6 -> 10
A7: Mai/26 | B7: 6 | C7: 5 | D7: =IFERROR(C7/B7,0) -> 0.83333333 | E7: =E6+C7 -> 15
A8: Jun/26 | B8: 4 | C8: 0 | D8: =IFERROR(C8/B8,0) -> 0 | E8: =E7+C8 -> 15
A9: Jul/26 | B9: 2 | C9: 0 | D9: =IFERROR(C9/B9,0) -> 0 | E9: =E8+C9 -> 15
A10: Ago/26 | B10: 1 | C10: 0 | D10: =IFERROR(C10/B10,0) -> 0 | E10: =E9+C10 -> 15
A11: Set/26 | B11: 1 | C11: 0 | D11: =IFERROR(C11/B11,0) -> 0 | E11: =E10+C11 -> 15

Sheet Custos
A1: CURVA S DE CUSTOS - EVM (PV / EV / AC)
A3: Mês | B3: PV - Valor Planejado | C3: EV - Valor Agregado | D3: AC - Custo Real | E3: Variação (EV-AC)
A4: Fev/26 | B4: 60000 | C4: 60000 | D4: 55000 | E4: =IFERROR(C4-D4,0) -> 5000
A5: Mar/26 | B5: 150000 | C5: 150000 | D5: 148000 | E5: =IFERROR(C5-D5,0) -> 2000
A6: Abr/26 | B6: 320000 | C6: 320000 | D6: 315000 | E6: =IFERROR(C6-D6,0) -> 5000
A7: Mai/26 | B7: 540000 | C7: 500000 | D7: 490000 | E7: =IFERROR(C7-D7,0) -> 10000
A8: Jun/26 | B8: 780000 | C8: 720000 | D8: 720000 | E8: =IFERROR(C8-D8,0) -> 0
A9: Jul/26 | B9: 1020000 | C9: 920000 | D9: 920000 | E9: =IFERROR(C9-D9,0) -> 0
A10: Ago/26 | B10: 1240000 | E10: =IFERROR(C10-D10,0) -> 0
A11: Set/26 | B11: 1380000 | E11: =IFERROR(C11-D11,0) -> 0
A12: Out/26 | B12: 1450000 | E12: =IFERROR(C12-D12,0) -> 0
A13: Nov/26 | B13: 1500000 | E13: =IFERROR(C13-D13,0) -> 0

Sheet Problemas
A1: PROBLEMAS E IMPEDIMENTOS ATUAIS
A3: ID | B3: Descrição | C3: Data de Abertura | D3: Responsável | E3: Prioridade | F3: Status
A4: P01 | B4: API do banco parceiro retornando erro 500 intermitente | C4: 05/05/2026 | D4: Dev Integração | E4: Alta | F4: Em Tratamento
A5: P02 | B5: Ambiente de homologação indisponível por 2 dias | C5: 10/05/2026 | D5: Infraestrutura | E5: Alta | F5: Em Tratamento
A6: P03 | B6: Falta de definição de regra de cálculo de juros | C6: 12/05/2026 | D6: Equipe Análise | E6: Média | F6: Aberto
A7: P04 | B7: Recurso de QA em férias sem cobertura prevista | C7: 08/05/2026 | D7: PMO | E7: Média | F7: Em Tratamento
A8: P05 | B8: Pentest apontou 3 vulnerabilidades médias | C8: 15/05/2026 | D8: Segurança TI | E8: Alta | F8: Aberto
A9: P06 | B9: Documentação técnica desatualizada para 2 módulos | C9: 13/05/2026 | D9: Tech Writer | E9: Baixa | F9: Aberto
A10: P07 | B10: Aprovação do jurídico pendente há 5 dias | C10: 12/05/2026 | D10: Jurídico | E10: Alta | F10: Aberto

Sheet Análise e Decisões
B2: ANÁLISE DO DASHBOARD - INDICADORES, INTERPRETAÇÃO E DECISÕES
B4: 1. INDICADORES ESCOLHIDOS E JUSTIFICATIVA
B5: Status Geral (semáforo) | C5: Resume em uma única cor (verde / amarelo / vermelho) a saúde do projeto, combinando o desempenho de prazo (SPI) e de custo (CPI). Importância: é o indicador de leitura rápida para sponsors e executivos.
B6: % de Conclusão | C6: Mede o avanço físico do projeto (atividades concluídas / total). Importância: mostra objetivamente quanto do projeto já foi entregue.
B7: CPI - Cost Performance Index | C7: CPI = EV / AC. Importância: indica a eficiência financeira. CPI ≥ 1 significa eficiência. CPI < 1 = estouro de orçamento.
B8: SPI - Schedule Performance Index | C8: SPI = EV / PV. Importância: aderência ao cronograma. SPI ≥ 1 = no prazo; SPI < 1 = atrasado.
B9: Aderência de Entregas (%) | C9: Razão entre entregas realizadas e planejadas. Importância: traduz prazo em algo tangível para governança.
B10: Atividades Atrasadas | C10: Número absoluto de atividades em atraso. Importância: indicador operacional direto - aponta onde atuar agora.
B11: Top Riscos | C11: Riscos com maior severidade (prob × impacto). Importância: foco gerencial nos riscos de maior exposição.
B12: Próximos Marcos | C12: Próximos pontos de controle. Importância: marcos sinalizam compromissos formais com stakeholders.
B13: Problemas / Impedimentos | C13: Issues atuais que bloqueiam o trabalho hoje. Diferente de riscos, precisam ser resolvidos no curto prazo.
B14: Curva S de Custos (PV / EV / AC) | C14: Visualiza valor planejado, valor agregado e custo real ao longo do tempo. Importância: a divergência entre as 3 curvas mostra problemas de prazo (PV vs EV) e custo (EV vs AC).
B15: Entregas Previstas x Realizadas (mensal) | C15: Visão histórica de entregas. Importância: revela tendência - se o gap cresce, há deterioração do projeto.
B16: Curva S de Entregas Acumuladas | C16: Mostra o acúmulo de entregas realizadas ao longo do tempo. Importância: o formato 'S' é esperado em projetos saudáveis; desvios indicam problemas de ritmo.
B17: Orçamento Consumido (%) | C17: Custo Real / Orçamento Total. Quando ultrapassa o % de conclusão, há sinal de estouro futuro.
B18: 2. INTERPRETAÇÃO DOS DADOS APRESENTADOS
B19: Visão geral | C19: Com 60% das atividades concluídas, CPI ≈ 1,06 e SPI ≈ 0,90, o projeto está saudável financeiramente, mas com leve atraso no cronograma. Status geral: 🟡 ATENÇÃO.
B20: Análise de prazo | C20: Aderência de 62,5% (15/24). 9 atividades atrasadas concentradas em integrações, frontend, segurança e compliance. Gargalo está em dependências externas.
B21: Análise de custo | C21: Custo real (R$ 920k) abaixo do valor agregado (R$ 975k). Mas orçamento consumido (61%) está alinhado com a conclusão (60%) - sem folga para absorver atrasos.
B22: Análise visual da Curva S | C22: Observando o gráfico PV/EV/AC: EV está abaixo de PV (atraso), mas AC < EV (eficiência de custo). Esse padrão é típico de projetos com bom time mas com problemas de planejamento ou dependências.
B23: Análise de riscos | C23: Dois riscos críticos (severidade ≥ 20): integração SAP e mudança de escopo. Categoria 'Técnico' e 'Pessoas' concentram a maior severidade total.
B24: Análise de problemas | C24: 7 issues, 4 de prioridade Alta. Maioria envolve dependências externas. Reforça o diagnóstico: o projeto está limitado por interfaces externas.
B25: 3. DECISÕES GERENCIAIS POSSÍVEIS
B26: Decisão 1 - Escalar problemas externos | C26: Acionar fornecedores (banco, SAP) com SLA reforçado; pedir intervenção do sponsor no jurídico.
B27: Decisão 2 - Replanejamento parcial | C27: Com SPI 0,90, considerar fast-tracking ou ajuste de janela de Go-Live para recuperar prazo.
B28: Decisão 3 - Reforço de recursos críticos | C28: Alocar dev sênior em integrações e cobrir férias do QA. Gargalo em recursos especializados.
B29: Decisão 4 - Tratamento dos riscos críticos | C29: Workshop de mitigação dos riscos R01 (SAP) e R02 (escopo) com sponsor. Definir plano B documentado.
B30: Decisão 5 - Reserva de contingência | C30: Solicitar 10% de contingência ao sponsor para horas extras e antecipação de pentest.
B31: Decisão 6 - Comunicação proativa | C31: Emitir Status Report executivo destacando SPI e riscos críticos. Transparência preserva confiança.
B32: 4. AUDIÊNCIAS DO DASHBOARD
B33: 👨‍💻 Equipe técnica | C33: Visão operacional detalhada: • Lista completa de atividades (aba Atividades) com responsáveis e datas. • Atividades atrasadas com nome do responsável. • Problemas e impedimentos abertos (prioridade Alta primeiro). • Próximos marcos para se organizar. Objetivo: foco no que precisa ser feito hoje e nas próximas semanas.
B34: 👩‍💼 Gerente do Projeto | C34: Visão de gestão tática (recebe TUDO): • Todos os KPIs do dashboard (status, %, CPI, SPI, aderência). • Matriz de riscos completa com plano de resposta. • Curva S de custos (PV/EV/AC) e tendência de entregas. • Atividades atrasadas + problemas + marcos. • Orçamento e variações. Objetivo: decidir replanejamentos, escalar problemas, atuar nos riscos.
B35: 👔 Executivos / Sponsor | C35: Visão estratégica e resumida: • Status geral (semáforo) - leitura em 5 segundos. • % de conclusão e aderência de entregas. • CPI / SPI. • Top 3-5 riscos críticos. • Próximos marcos relevantes (Go-Live, UAT). • Curva S consolidada (visão única do orçamento). Objetivo: avaliar saúde do investimento, decidir continuidade, destravar bloqueios. NÃO recebem detalhe operacional.
B36: 5. ELEMENTOS VISUAIS UTILIZADOS NO DASHBOARD
B37: Semáforos coloridos | C37: Aplicados em: status geral, indicadores EVM (CPI/SPI/CV/Aderência), severidade de riscos, prioridade de problemas, status de marcos. Permitem leitura instantânea (verde/amarelo/vermelho).
B38: Barras de progresso (Data Bars) | C38: Mostram o % de conclusão de cada atividade de forma visual dentro da própria célula. Aplicados na lista de atividades e no card de atividades atrasadas.
B39: Escalas de cor (Color Scales) | C39: Gradientes que vão do verde ao vermelho conforme o valor. Usados em: % conclusão, aderência de entregas, dias de atraso, variação de custo.
B40: Gráfico de Rosca / Donut | C40: Distribuição de atividades por status; orçamento consumido vs disponível. Visualização clara de proporções.
B41: Gráfico de Pizza | C41: Distribuição de problemas por prioridade. Mostra rapidamente a concentração de issues críticos.
B42: Gráfico de Barras (vertical e horizontal) | C42: Entregas previstas x realizadas (vertical); riscos por categoria (horizontal). Permite comparação direta entre categorias.
...
