Workbook

Sheet Dashboard
B2: DASHBOARD DE GESTÃO DE PROJETO · KYBERNUS CLI
B3: =CONCATENATE("Projeto: ",'Parâmetros'!$C$5," | GP: ",'Parâmetros'!$C$6," | Data de Status: ",'Parâmetros'!$C$10) -> Projeto: Kybernus CLI | GP: Guilherme Marafon | Data de Status: 31/05/2026
B5: VISÃO GERAL
B7: STATUS GERAL | E7: % DE CONCLUSÃO | H7: PRAZO · SPI | K7: CUSTO · CPI | N7: ORÇAMENTO CONSUMIDO
B8: =IF(AND(Dados!$B$43>=0.95,Dados!$B$45>=0.95),"🟢 NO PRAZO",IF(OR(Dados!$B$43<0.85,Dados!$B$45<0.85),"🔴 CRÍTICO","🟡 ATENÇÃO")) -> 🟢 NO PRAZO | E8: ='Parâmetros'!$C$17 -> 0.611 | H8: =Dados!$B$43 -> 0.99983636 | K8: =Dados!$B$45 -> 1.0000479 | N8: =Dados!$B$48 -> 0.61097072
B10: ="Prazo + Custo (EVM)" -> Prazo + Custo (EVM) | E10: =CONCATENATE("Planejado: ",TEXT('Parâmetros'!$C$23,"0%")) -> Planejado: 61% | H10: =IF(Dados!$B$43>=0.95,"No ritmo","Atraso de cronograma") -> No ritmo | K10: =IF(Dados!$B$45>=1,"Dentro do custo","Acima do custo") -> Dentro do custo | N10: =CONCATENATE("de ",TEXT('Parâmetros'!$C$13,"R$ #,##0")) -> de R$ 32.450
B12: ⏱ INDICADORES DE PRAZO E CUSTO (EVM)
B13: Indicador | E13: Valor | F13: Faixa OK | G13: ● | H13: Interpretação | K13: 📌 SITUAÇÃO DAS ATIVIDADES
B14: CPI — Desempenho de Custo | E14: =Dados!$B$45 -> 1.0000479 | F14: ≥ 0,95 | G14: ● | H14: =IF(Dados!$B$45>=1,"Eficiência de custo — EV acima do AC","Custo acima do previsto") -> Eficiência de custo — EV acima do AC | K14: ='Parâmetros'!$C$19 -> 48 | M14: ='Parâmetros'!$C$20 -> 3 | O14: =Dados!$B$44 -> 19826.95
B15: SPI — Desempenho de Prazo | E15: =Dados!$B$43 -> 0.99983636 | F15: ≥ 0,95 | G15: ● | H15: =IF(Dados!$B$43>=0.95,"Cronograma no ritmo","Atraso em relação ao plano") -> Cronograma no ritmo | K15: Concluídas | M15: Em Execução | O15: EV — Valor Agregado
B16: CV — Variação de Custo (R$) | E16: =Dados!$B$47 -> 0.95 | F16: ≥ 0 | G16: ● | H16: =IF(Dados!$B$47>=0,"Dentro do orçamento","Estouro de custo") -> Dentro do orçamento | K16: ='Parâmetros'!$C$21 -> 0 | M16: ='Parâmetros'!$C$22 -> 32 | O16: =Dados!$B$46 -> 19830.195
B17: Avanço Real vs Planejado | E17: ='Parâmetros'!$C$17 -> 0.611 | F17: — | G17: ● | H17: =CONCATENATE("Real ",TEXT('Parâmetros'!$C$17,"0%")," / Plan. ",TEXT('Parâmetros'!$C$23,"0%")) -> Real 61% / Plan. 61% | K17: Atrasadas | M17: Não Iniciadas | O17: PV — Valor Planejado
B22: 📈 INDICADORES VISUAIS
B56: 🎯 PRÓXIMOS MARCOS | J56: ⚠ TOP RISCOS CRÍTICOS
B57: Marco | E57: Data | G57: Situação | J57: Risco | O57: Sev. | P57: Nível
B58: Gerenciamento do Projeto | E58: 11/03/2026 | G58: Concluído | J58: R02 · Mudanças no escopo não controladas | O58: 12 | P58: 🟡
B59: Definição e Design | E59: 01/04/2026 | G59: Concluído | J59: R06 · Disponibilidade limitada da equipe impactando o cronograma | O59: 12 | P59: 🟡
B60: Implementação das Funcionalidades | E60: 03/06/2026 | G60: Previsto | J60: R12 · Mudanças estruturais em frameworks suportados quebrando os templates gerados | O60: 12 | P60: 🟡
B61: Testes e Documentação | E61: 17/06/2026 | G61: Previsto | J61: R08 · Dependência excessiva de um único integrante em partes críticas do projeto | O61: 9 | P61: 🟡
B62: Divulgação e Encerramento | E62: 01/07/2026 | G62: Previsto | J62: R11 · Incompatibilidade entre os módulos durante a integração da ferramenta | O62: 9 | P62: 🟡
J63: R13 · Baixa qualidade das saídas geradas pela IA devido a prompts mal calibrados | O63: 9 | P63: 🟡
B65: 🛡 PLANO DE RESPOSTA AOS RISCOS PRIORITÁRIOS
B66: Risco | J66: Ação | N66: Estratégia | P66: Responsável
B67: R02 · Mudanças no escopo não controladas | J67: Mitigar | N67: Gestão do projeto | P67: GP
B68: R06 · Disponibilidade limitada da equipe impactando o cronograma | J68: Aceitar | N68: Organizacional | P68: GP
B69: R12 · Mudanças estruturais em frameworks suportados quebrando os templates gerados | J69: Aceitar | N69: Técnico | P69: Devs
B70: R08 · Dependência excessiva de um único integrante em partes críticas do projeto | J70: Mitigar | N70: Organizacional | P70: GP
B71: R11 · Incompatibilidade entre os módulos durante a integração da ferramenta | J71: Mitigar | N71: Técnico | P71: Devs

Sheet Parâmetros
B2: ⚙ PARÂMETROS DO PROJETO — KYBERNUS CLI
E3: 💡 Esta aba centraliza as variáveis do projeto. Os campos de STATUS REAL (em amarelo) são editáveis — ao atualizá-los o Dashboard recalcula sozinho. Os valores-padrão assumem o projeto "em dia" com o cronograma (avanço 61% na data de status). Substitua pelos números reais do andamento para o semáforo refletir a situação atual.
B4: IDENTIFICAÇÃO E BASELINE
B5: Nome do Projeto | C5: Kybernus CLI
B6: Gerente do Projeto (GP) | C6: Guilherme Marafon
B7: Patrocinadora | C7: Prof. Rosilene
B8: Data de Início | C8: 04/03/2026
B9: Data de Término Planejada | C9: 01/07/2026
B10: Data de Status (Reporte) | C10: 31/05/2026
B11: Total de Atividades | C11: 83
B12: Total de Horas Planejadas (h) | C12: 1008
B13: Orçamento Aprovado — BAC (R$) | C13: 32450
B14: Custo Planejado — cronograma (R$) | C14: 27130
B16: STATUS REAL (EDITÁVEL)
B17: Avanço Real do Projeto (%) | C17: 0.611
B18: Custo Real Acumulado — AC (R$) | C18: 19826
B19: Atividades Concluídas | C19: 48
B20: Atividades em Execução | C20: 3
B21: Atividades Atrasadas | C21: 0
B22: Atividades Não Iniciadas | C22: 32
B23: Avanço Planejado (cronograma) | C23: 0.6111

Sheet Cronograma
A1: 📅 CRONOGRAMA COMPLETO — KYBERNUS CLI
A2: ID | B2: EAP | C2: Tarefa | D2: Início | E2: Término | F2: Dur (du) | G2: Horas | H2: Responsável
A3: FASE 1 · Gerenciamento do Projeto
A4: 4 | B4: 1.1 | C4: Elaborar o Termo de Abertura do Projeto (TAP) | D4: 04/03/2026 | E4: 06/03/2026 | F4: 4 | G4: 8 | H4: GP
A5: 5 | B5: 1.1 | C5: Apresentar e obter aprovação da patrocinadora | D5: 09/03/2026 | E5: 09/03/2026 | F5: 2 | G5: 4 | H5: GP
A6: 6 | B6: 1.1 | C6: Designar formalmente o gerente do projeto | D6: 09/03/2026 | E6: 09/03/2026 | F6: 1 | G6: 2 | H6: PAT
A7: 8 | B7: 1.2 | C7: Construir a EAP (fases e subentregas) | D7: 10/03/2026 | E7: 12/03/2026 | F7: 4 | G7: 8 | H7: GP+PM
A8: 9 | B8: 1.2 | C8: Elaborar o Dicionário da EAP | D8: 13/03/2026 | E8: 13/03/2026 | F8: 2 | G8: 4 | H8: GP
A9: 10 | B9: 1.2 | C9: Definir e documentar processo de controle de mudanças | D9: 16/03/2026 | E9: 16/03/2026 | F9: 2 | G9: 4 | H9: GP
A10: 12 | B10: 1.3 | C10: Identificar e classificar os stakeholders | D10: 13/03/2026 | E10: 13/03/2026 | F10: 2 | G10: 4 | H10: PM
A11: 13 | B11: 1.3 | C11: Elaborar mapa e registro de stakeholders | D11: 16/03/2026 | E11: 16/03/2026 | F11: 2 | G11: 4 | H11: PM
A12: 14 | B12: 1.3 | C12: Definir estratégia de engajamento e plano de comunicação | D12: 17/03/2026 | E12: 17/03/2026 | F12: 2 | G12: 4 | H12: GP
A13: 16 | B13: 1.4 | C13: Identificar e descrever os riscos | D13: 18/03/2026 | E13: 18/03/2026 | F13: 2 | G13: 4 | H13: GP
A14: 17 | B14: 1.4 | C14: Analisar probabilidade e impacto (matriz P×I) | D14: 19/03/2026 | E14: 19/03/2026 | F14: 2 | G14: 4 | H14: GP
A15: 18 | B15: 1.4 | C15: Definir planos de resposta e contingência | D15: 20/03/2026 | E15: 24/03/2026 | F15: 4 | G15: 8 | H15: GP
... A21: 26 | B21: 1.6 | C21: Obter aceite formal da patrocinadora | D21: 01/07/2026 | E21: 01/07/2026 | F21: 1 | G21: 2 | H21: PAT
A22: FASE 2 · Definição e Design
A23: 29 | B23: 2.1 | C23: Levantar e documentar RFs e RNFs com stakeholders | D23: 25/03/2026 | E23: 31/03/2026 | F23: 6 | G23: 12 | H23: PM+GP
A24: 30 | B24: 2.1 | C24: Priorizar requisitos com PM (Alta/Média/Baixa) | D24: 01/04/2026 | E24: 02/04/2026 | F24: 3 | G24: 6 | H24: PM
A25: 31 | B25: 2.1 | C25: Definir critérios de aceite por requisito | D25: 03/04/2026 | E25: 06/04/2026 | F25: 3 | G25: 6 | H25: PM+GP
A26: 33 | B26: 2.2 | C26: Definir arquitetura dos 4 módulos do CLI | D26: 07/04/2026 | E26: 07/04/2026 | F26: 1 | G26: 8 | H26: Dev #1+Dev #2+Dev #3
A27: 34 | B27: 2.2 | C27: Especificar contratos de interface entre módulos | D27: 08/04/2026 | E27: 08/04/2026 | F27: 1 | G27: 8 | H27: Dev #1+Dev #2+Dev #3
A28: 35 | B28: 2.2 | C28: Validar e decidir serviços externos | D28: 09/04/2026 | E28: 09/04/2026 | F28: 1 | G28: 8 | H28: Dev #1+Dev #2+Dev #3+PM
A29: 37 | B29: 2.3 | C29: Especificar templates por stack (6 linguagens) | D29: 10/04/2026 | E29: 10/04/2026 | F29: 2 | G29: 12 | H29: Dev #1
A30: 38 | B30: 2.3 | C30: Especificar templates por arquitetura | D30: 13/04/2026 | E30: 13/04/2026 | F30: 1 | G30: 8 | H30: Dev #1
A31: 39 | B31: 2.3 | C31: Especificar templates DevOps | D31: 10/04/2026 | E31: 10/04/2026 | F31: 1 | G31: 8 | H31: Dev #2
A32: 41 | B32: 2.4 | C32: Desenhar fluxo interativo com menus visuais | D32: 14/04/2026 | E32: 14/04/2026 | F32: 1 | G32: 8 | H32: Dev #1+Dev #2+Dev #3
A33: 42 | B33: 2.4 | C33: Especificar flags não-interativas | D33: 15/04/2026 | E33: 15/04/2026 | F33: 1 | G33: 4 | H33: Dev #1
A34: 43 | B34: 2.4 | C34: Definir formato do painel de next steps | D34: 15/04/2026 | E34: 15/04/2026 | F34: 1 | G34: 4 | H34: Dev #3+PM
... A36: 46 | B36: 2.5 | C36: Registrar baseline do escopo e comunicar à equipe | D36: 17/04/2026 | E36: 17/04/2026 | F36: 1 | G36: 2 | H36: GP
A37: FASE 3 · Implementação das Funcionalidades
A38: 49 | B38: 3.1 | C38: Implementar interface interativa com menus (RF01–RF04) | D38: 22/04/2026 | E38: 23/04/2026 | F38: 3 | G38: 24 | H38: Dev #1
A39: 50 | B39: 3.1 | C39: Implementar flags não-interativas e modo CI/CD (RF15) | D39: 24/04/2026 | E39: 24/04/2026 | F39: 2 | G39: 20 | H39: Dev #1
A40: 51 | B40: 3.1 | C40: Implementar kybernus doctor — verificação de ambiente | D40: 25/04/2026 | E40: 25/04/2026 | F40: 2 | G40: 16 | H40: Dev #1
A41: 53 | B41: 3.2 | C41: Implementar geração de estrutura por stack + arquitetura | D41: 28/04/2026 | E41: 02/05/2026 | F41: 4 | G41: 32 | H41: Dev #1
A42: 54 | B42: 3.2 | C42: Implementar templates Node.js+Express e NestJS (RF21) | D42: 05/05/2026 | E42: 05/05/2026 | F42: 2 | G42: 16 | H42: Dev #1
A43: 55 | B43: 3.2 | C43: Implementar templates FastAPI e Spring Boot (RF22,RF23) | D43: 05/05/2026 | E43: 05/05/2026 | F43: 2 | G43: 16 | H43: Dev #2
A44: 56 | B44: 3.2 | C44: Implementar templates Next.js e n8n | D44: 06/05/2026 | E44: 06/05/2026 | F44: 2 | G44: 20 | H44: Dev #2
A45: 57 | B45: 3.2 | C45: Gerar arquivos base: .env, ESLint, Prettier (RF20) | D45: 06/05/2026 | E45: 06/05/2026 | F45: 2 | G45: 16 | H45: Dev #1
A46: 59 | B46: 3.3 | C46: Implementar geração de Docker + GH Actions + Terraform | D46: 07/05/2026 | E46: 12/05/2026 | F46: 3 | G46: 24 | H46: Dev #2
...

Sheet Marcos
B2: 🎯 MARCOS DO PROJETO (Plano de Projeto)
B4: ID | C4: Marco | D4: Data Prevista | E4: Situação
B5: M0 | C5: Gerenciamento do Projeto | D5: 11/03/2026 | E5: Concluído
B6: M1 | C6: Definição e Design | D6: 01/04/2026 | E6: Concluído
B7: M2 | C7: Implementação das Funcionalidades | D7: 03/06/2026 | E7: Previsto
B8: M3 | C8: Testes e Documentação | D8: 17/06/2026 | E8: Previsto
B9: M4 | C9: Divulgação e Encerramento | D9: 01/07/2026 | E9: Previsto

Sheet Riscos
B2: ⚠ MATRIZ DE RISCOS — KYBERNUS CLI (Plano de Riscos GP02)
B4: Cód. | C4: Descrição do Risco | D4: Categoria | E4: Prob. | F4: Imp. | G4: Sev. | H4: Nível | I4: Ação | J4: Responsável
B5: 2 | C5: Mudanças no escopo não controladas | D5: Gestão do projeto | E5: 3 | F5: 4 | G5: 12 | H5: =IF(G5>=15,"🔴 Alto",IF(G5>=8,"🟡 Médio","🟢 Baixo")) -> 🟡 Médio | I5: Mitigar | J5: Gerente do Projeto
B6: 6 | C6: Disponibilidade limitada da equipe impactando o cronograma | D6: Organizacional | E6: 4 | F6: 3 | G6: 12 | H6: =IF(G6>=15,"🔴 Alto",IF(G6>=8,"🟡 Médio","🟢 Baixo")) -> 🟡 Médio | I6: Aceitar | J6: Gerente do Projeto
B7: 12 | C7: Mudanças estruturais em frameworks suportados quebrando os templates gerados | D7: Técnico | E7: 4 | F7: 3 | G7: 12 | H7: =IF(G7>=15,"🔴 Alto",IF(G7>=8,"🟡 Médio","🟢 Baixo")) -> 🟡 Médio | I7: Aceitar | J7: Desenvolvedores
B8: 8 | C8: Dependência excessiva de um único integrante em partes críticas do projeto | D8: Organizacional | E8: 3 | F8: 3 | G8: 9 | H8: =IF(G8>=15,"🔴 Alto",IF(G8>=8,"🟡 Médio","🟢 Baixo")) -> 🟡 Médio | I8: Mitigar | J8: Gerente do Projeto
B9: 11 | C9: Incompatibilidade entre os módulos durante a integração da ferramenta | D9: Técnico | E9: 3 | F9: 3 | G9: 9 | H9: =IF(G9>=15,"🔴 Alto",IF(G9>=8,"🟡 Médio","🟢 Baixo")) -> 🟡 Médio | I9: Mitigar | J9: Desenvolvedores
B10: 13 | C10: Baixa qualidade das saídas geradas pela IA devido a prompts mal calibrados | D10: Técnico | E10: 3 | F10: 3 | G10: 9 | H10: =IF(G10>=15,"🔴 Alto",IF(G10>=8,"🟡 Médio","🟢 Baixo")) -> 🟡 Médio | I10: Mitigar | J10: Desenvolvedores
B11: 4 | C11: Entregas não atenderem aos critérios de aceitação definidos no TAP | D11: Técnico | E11: 2 | F11: 4 | G11: 8 | H11: =IF(G11>=15,"🔴 Alto",IF(G11>=8,"🟡 Médio","🟢 Baixo")) -> 🟡 Médio | I11: Mitigar | J11: Gerente do Projeto
B12: 7 | C12: Saída de um integrante da equipe durante o projeto | D12: Organizacional | E12: 2 | F12: 4 | G12: 8 | H12: =IF(G12>=15,"🔴 Alto",IF(G12>=8,"🟡 Médio","🟢 Baixo")) -> 🟡 Médio | I12: Mitigar | J12: Gerente do Projeto
B13: 14 | C13: Falha de segurança na transmissão dos dados de telemetria expondo informações dos usuários | D13: Técnico | E13: 2 | F13: 4 | G13: 8 | H13: =IF(G13>=15,"🔴 Alto",IF(G13>=8,"🟡 Médio","🟢 Baixo")) -> 🟡 Médio | I13: Tranferir | J13: Desenvolvedores
B14: 1 | C14: Estimativas de prazo incorretas na fase de planejamento gerando atrasos no cronograma | D14: Gestão do projeto | E14: 3 | F14: 3 | G14: 6 | H14: =IF(G14>=15,"🔴 Alto",IF(G14>=8,"🟡 Médio","🟢 Baixo")) -> 🟢 Baixo | I14: Mitigar | J14: Gerente do Projeto
B15: 3 | C15: Falha na comunicação entre os membros da equipe gerando retrabalho | D15: Gestão do projeto | E15: 3 | F15: 2 | G15: 6 | H15: =IF(G15>=15,"🔴 Alto",IF(G15>=8,"🟡 Médio","🟢 Baixo")) -> 🟢 Baixo | I15: Mitigar | J15: Gerente do Projeto
B16: 5 | C16: Falta de revisão do plano de projeto | D16: Gestão do projeto | E16: 2 | F16: 3 | G16: 6 | H16: =IF(G16>=15,"🔴 Alto",IF(G16>=8,"🟡 Médio","🟢 Baixo")) -> 🟢 Baixo | I16: Mitigar | J16: Gerente do Projeto
... B24: 15 | C24: Falha na publicação ou distribuição via npm impedindo o acesso dos usuários | D24: Técnico | E24: 1 | F24: 2 | G24: 2 | H24: =IF(G24>=15,"🔴 Alto",IF(G24>=8,"🟡 Médio","🟢 Baixo")) -> 🟢 Baixo | I24: Aceitar | J24: Desenvolvedores

Sheet Recursos e Custos
B2: 👥 ALOCAÇÃO DE RECURSOS (Planejado vs Teto TAP)
B4: Cód. | C4: Integrante | D4: Função | E4: Limite TAP (h) | F4: Planejadas (h) | G4: % Util. | H4: Saldo (h) | I4: Status
B5: GP | C5: Guilherme Marafon | D5: Gerente de Projetos | E5: 160 | F5: 142 | G5: =F5/E5 -> 0.8875 | H5: =E5-F5 -> 18 | I5: =IF(G5>1,"🔴 ACIMA",IF(G5>0.9,"🟡 LIMITE","🟢 OK")) -> 🟢 OK
B6: PM | C6: Giulia Castelucci | D6: Product Manager | E6: 80 | F6: 49 | G6: =F6/E6 -> 0.6125 | H6: =E6-F6 -> 31 | I6: =IF(G6>1,"🔴 ACIMA",IF(G6>0.9,"🟡 LIMITE","🟢 OK")) -> 🟢 OK
B7: Dev #1 | C7: Vinícius Trevisan | D7: Desenvolvedor | E7: 330 | F7: 273 | G7: =F7/E7 -> 0.82727273 | H7: =E7-F7 -> 57 | I7: =IF(G7>1,"🔴 ACIMA",IF(G7>0.9,"🟡 LIMITE","🟢 OK")) -> 🟢 OK
B8: Dev #2 | C8: Guilherme Reis | D8: Desenvolvedor | E8: 330 | F8: 257 | G8: =F8/E8 -> 0.77878788 | H8: =E8-F8 -> 73 | I8: =IF(G8>1,"🔴 ACIMA",IF(G8>0.9,"🟡 LIMITE","🟢 OK")) -> 🟢 OK
B9: Dev #3 | C9: Amanda Freire | D9: Desenvolvedor | E9: 330 | F9: 309 | G9: =F9/E9 -> 0.93636364 | H9: =E9-F9 -> 21 | I9: =IF(G9>1,"🔴 ACIMA",IF(G9>0.9,"🟡 LIMITE","🟢 OK")) -> 🟡 LIMITE
B10: MKT | C10: Valentina Lago | D10: Marketing | E10: 20 | F10: 17 | G10: =F10/E10 -> 0.85 | H10: =E10-F10 -> 3 | I10: =IF(G10>1,"🔴 ACIMA",IF(G10>0.9,"🟡 LIMITE","🟢 OK")) -> 🟢 OK
B12: 💰 ANÁLISE DE CUSTOS (Planejado vs Teto TAP)
B14: Cód. | C14: Integrante | D14: Horas | E14: R$/h | F14: Custo Planejado | G14: Custo TAP | H14: Diferença
B15: GP | C15: Guilherme Marafon | D15: 142 | E15: 30 | F15: =D15*E15 -> 4260 | G15: 4800 | H15: =F15-G15 -> -540
B16: PM | C16: Giulia Castelucci | D16: 49 | E16: 30 | F16: =D16*E16 -> 1470 | G16: 2400 | H16: =F16-G16 -> -930
B17: Dev #1 | C17: Vinícius Trevisan | D17: 273 | E17: 25 | F17: =D17*E17 -> 6825 | G17: 8250 | H17: =F17-G17 -> -1425
B18: Dev #2 | C18: Guilherme Reis | D18: 257 | E18: 25 | F18: =D18*E18 -> 6425 | G18: 8250 | H18: =F18-G18 -> -1825
B19: Dev #3 | C19: Amanda Freire | D19: 309 | E19: 25 | F19: =D19*E19 -> 7725 | G19: 8250 | H19: =F19-G19 -> -525
B20: MKT | C20: Valentina Lago | D20: 17 | E20: 25 | F20: =D20*E20 -> 425 | G20: 500 | H20: =F20-G20 -> -75
C21: TOTAL | F21: =SUM(F15:F20) -> 27130 | G21: =SUM(G15:G20) -> 32450 | H21: =SUM(H15:H20) -> -5320
B23: 💸 CUSTO POR FASE (baseline — Plano de Custo)
B25: Fase | D25: Custo (R$) | E25: % do Total
B26: F1 · Gerenciamento | D26: 4800 | E26: =D26/32450 -> 0.14791988
B27: F2 · Definição & Design | D27: 3894 | E27: =D27/32450 -> 0.12
B28: F3 · Implementação | D28: 16874 | E28: =D28/32450 -> 0.52
B29: F4 · Testes & Doc. | D29: 6490 | E29: =D29/32450 -> 0.2
B30: F5 · Divulgação & Encerr. | D30: 5192 | E30: =D30/32450 -> 0.16
B31: TOTAL | D31: =SUM(D26:D30) -> 37250 | E31: 1
B33: Obs.: infraestrutura (Gemini, PostHog, Supabase, npm, Vercel) em planos gratuitos — R$ 0,00. Custo por fase cobre o esforço técnico; GP é transversal.

Sheet Partes Interessadas
B2: 🤝 PARTES INTERESSADAS — Engajamento (Plano de Expectativas)
B4: Parte Interessada | C4: Engajamento | D4: Impacto | E4: Estratégia de Engajamento
B5: Patrocinadora (Prof. Rosilene) | C5: A → L | D5: Alto | E5: Reuniões periódicas de prestação de contas com entregas e critérios de aceite claros; envolvê-la nas decisões de escopo.
B6: Gerente de Projeto (G. Marafon) | C6: L → L | D6: Alto | E6: Autonomia para decisões operacionais e acesso a informações em tempo real via ClickUp.
B7: Product Manager (G. Castelucci) | C7: A → L | D7: Alto | E7: Envolver nas decisões de priorização de requisitos e validação de escopo; reconhecer contribuições.
B8: Desenvolvedores (#1,#2,#3) | C8: A → L | D8: Alto | E8: Clareza nas tarefas e autonomia técnica; reconhecer contribuições e evitar sobrecarga além do TAP.
B9: Consultor de Marketing (V. Lago) | C9: N → A | D9: Médio | E9: Mostrar impacto estratégico do lançamento; envolver no posicionamento desde a Fase 4.
B10: Tech Leads / Arquitetos | C10: D → A | D10: Médio | E10: Compartilhar documentação técnica e padrões (MVC, Clean, Hexagonal); convidar para testes externos.
B11: Desenvolvedores (usuários finais) | C11: D → A | D11: Alto | E11: Landing page clara com instruções; garantir meta de 80% de sucesso sem suporte.
B12: Comunidade Open-Source | C12: D → A | D12: Médio | E12: Repositório modelo no GitHub (README, CONTRIBUTING, templates); divulgar no dev.to e Product Hunt.
B13: Empresas de Tecnologia | C13: D → N | D13: Baixo | E13: Monitorar interesse via telemetria após o lançamento; sem ação direta no ciclo atual.
B15: Legenda engajamento: A=Apoiador · N=Neutro · R=Resistente · D=Desinformado · L=Lidera. (atual → desejado)

Sheet Dados
A1: TABELAS DE APOIO AOS GRÁFICOS (não editar)
A3: Fase | B3: Horas Totais | C3: Horas Concluídas | D3: % Concl.
A4: F1 · Gerenciamento | B4: 94 | C4: 58 | D4: =C4/B4 -> 0.61702128
A5: F2 · Definição & Design | B5: 96 | C5: 96 | D5: =C5/B5 -> 1
A6: F3 · Implementação | B6: 518 | C6: 462 | D6: =C6/B6 -> 0.89189189
A7: F4 · Testes & Doc. | B7: 234 | C7: 0 | D7: =C7/B7 -> 0
A8: F5 · Divulgação & Encerr. | B8: 66 | C8: 0 | D8: =C8/B8 -> 0
A10: Mês | B10: Acumulado Planejado (h) | C10: Acumulado Realizado (h)
A11: Mar/26 | B11: 70 | C11: =B11*('Parâmetros'!$C$17/'Parâmetros'!$C$23) -> 69.988545
A12: Abr/26 | B12: 214 | C12: =B12*('Parâmetros'!$C$17/'Parâmetros'!$C$23) -> 213.96498
A13: Mai/26 | B13: 616 | C13: =B13*('Parâmetros'!$C$17/'Parâmetros'!$C$23) -> 615.8992
A14: Jun/26 | B14: 980
A15: Jul/26 | B15: 1008
A17: Recurso | B17: % Utilização | C17: Planejadas (h) | D17: Limite TAP (h)
A18: GP | B18: =C18/D18 -> 0.8875 | C18: 142 | D18: 160
A19: PM | B19: =C19/D19 -> 0.6125 | C19: 49 | D19: 80
A20: Dev #1 | B20: =C20/D20 -> 0.82727273 | C20: 273 | D20: 330
A21: Dev #2 | B21: =C21/D21 -> 0.77878788 | C21: 257 | D21: 330
A22: Dev #3 | B22: =C22/D22 -> 0.93636364 | C22: 309 | D22: 330
A23: MKT | B23: =C23/D23 -> 0.85 | C23: 17 | D23: 20
A25: Categoria | B25: Severidade
A26: Técnico | B26: 48
A27: Organizacional | B27: 47
A28: Gestão do projeto | B28: 30
A29: Externo | B29: 13
A30: Aquisições | B30: 6
A32: Fase | B32: Custo (R$)
A33: F1 · Gerenciamento | B33: 4800
A34: F2 · Definição & Design | B34: 3894
A35: F3 · Implementação | B35: 16874
A36: F4 · Testes & Doc. | B36: 6490
A37: F5 · Divulgação & Encerr. | B37: 5192
A42: EVM (auto)
A43: SPI | B43: ='Parâmetros'!$C$17/'Parâmetros'!$C$23 -> 0.99983636
A44: EV | B44: ='Parâmetros'!$C$17*'Parâmetros'!$C$13 -> 19826.95
A45: CPI | B45: =('Parâmetros'!$C$17*'Parâmetros'!$C$13)/'Parâmetros'!$C$18 -> 1.0000479
A46: PV | B46: ='Parâmetros'!$C$23*'Parâmetros'!$C$13 -> 19830.195
A47: CV | B47: =('Parâmetros'!$C$17*'Parâmetros'!$C$13)-'Parâmetros'!$C$18 -> 0.95
A48: %ORC | B48: ='Parâmetros'!$C$18/'Parâmetros'!$C$13 -> 0.61097072
